<?xml version = "1.0"?>
<robot xmlns:xacro="http://www.ros.org/wiki/xacro">

  <xacro:macro name="pantograph" params="parent *origin">

  <material name="white_alpha">
    <color rgba="${255/255} ${255/255} ${255/255} 0.6"/>
  </material>

  <material name="blue">
    <color rgba="0.0 0.0 0.8 1.0"/>
  </material>

  <material name="green">
    <color rgba="0.0 0.8 0.0 1.0"/>
  </material>

  <material name="orange">
    <color rgba="${255/255} ${108/255} ${10/255} 1.0"/>
  </material>

  <!-- ========== Base link ========== -->

  <link name = "panto_base">
    <visual>
      <geometry>
        <mesh filename="package://pantograph_description/meshes/mesh_base.stl" scale="0.001 0.001 0.001"/>
      </geometry>
      <material name = "white_alpha"/>
      <origin xyz="0 0 0" rpy="0 0 0" />
    </visual>
  </link>

  <joint name="panto_root_joint" type="fixed">
      <xacro:insert_block name="origin" />
      <parent link="${parent}"/>
      <child link="panto_base"/>
  </joint>

  <!-- ==========  Fulcrum =========== -->

  <link name = "panto_link_fulcrum">
    <visual>
      <geometry>
        <mesh filename="package://pantograph_description/meshes/mesh_fulcrum.stl" scale="0.001 0.001 0.001"/>
      </geometry>
      <material name = "white_alpha"/>
      <origin xyz = "0 0 0" rpy = "0 0 0"/>
    </visual>
  </link>

  <joint name = "panto_base_to_fulcrum" type="fixed">
    <parent link = "panto_base"/>
    <child link = "panto_link_fulcrum"/>
    <origin xyz = "0.0425 0.16056 0.09"/>
  </joint>


  <!-- ==========  Left arm (as seen from behind) =========== -->

  <link name = "panto_left_motor">
    <inertial>
      <!-- izz = 69.9 g/cm², see https://www.farnell.com/datasheets/484832.pdf -->
      <mass value="0.1"/>
      <inertia ixx="0.1" ixy="0.0" ixz="0.0" iyy="0.1" iyz="0.0" izz="0.00000699"/>
    </inertial>
  </link>

  <joint name = "panto_a1" type="revolute">
    <parent link = "panto_base"/>
    <child link = "panto_left_motor"/>
    <origin xyz = "0.0 0 0" rpy="0 0 0"/>
    <limit effort="1000.0" lower="-1.57" upper="1.57" velocity="0.5"/>
    <axis xyz = "0 0 1"/>
    <dynamics damping="0.2" friction="0.1" />
  </joint>

  <link name = "panto_left_link1">
    <visual>
      <geometry>
        <mesh filename="package://pantograph_description/meshes/mesh_link_left_1.stl" scale="0.001 0.001 0.001"/>
      </geometry>
      <material name = "green"/>
      <origin xyz = "0 0 0" rpy = "0 0 0"/>
    </visual>
  </link>

  <joint name = "panto_left_motor_to_link1" type="fixed">
    <parent link = "panto_left_motor"/>
    <child link = "panto_left_link1"/>
    <origin xyz = "0 0 0"/>
  </joint>

  <link name = "panto_left_link2">
    <visual>
      <geometry>
        <mesh filename="package://pantograph_description/meshes/mesh_link_left_2.stl" scale="0.001 0.001 0.001"/>
      </geometry>
      <material name = "green"/>
      <origin xyz = "0 0 0" rpy = "0 0 0"/>
    </visual>
  </link>

  <joint name = "panto_a2" type="revolute">
    <parent link = "panto_left_link1"/>
    <child link = "panto_left_link2"/>
    <origin xyz = "0.1 0 0" rpy="0 0 0"/>
    <limit effort="1000.0" lower="-1.57" upper="1.57" velocity="0.5"/>
    <axis xyz = "0 0 1"/>
    <dynamics damping="0.2" friction="0.1" />
  </joint>

  <!-- ==========  Tool link (orange sphere) =========== -->

  <link name = "panto_tool0">
    <visual>
      <geometry>
        <mesh filename="package://pantograph_description/meshes/mesh_tool0.stl" scale="0.001 0.001 0.001"/>
      </geometry>
      <material name = "orange"/>
      <origin xyz = "0 0 0" rpy = "0 0 0"/>
    </visual>
  </link>

  <joint name = "panto_a3" type="revolute">
    <parent link = "panto_left_link2"/>
    <child link = "panto_tool0"/>
    <origin xyz = "0.165 0 0" rpy="0 0 0"/>
    <limit effort="1000.0" lower="-1.57" upper="1.57" velocity="0.5"/>
    <axis xyz = "0 0 1"/>
    <dynamics damping="0.2" friction="0.1" />
  </joint>

  <!-- ==========  Right arm (as seen from behind) =========== -->

  <link name = "panto_right_motor">
    <inertial>
      <!-- izz = 69.9 g/cm², see https://www.farnell.com/datasheets/484832.pdf -->
      <mass value="0.1"/>
      <inertia ixx="0.1" ixy="0.0" ixz="0.0" iyy="0.1" iyz="0.0" izz="0.00000699"/>
    </inertial>
  </link>

  <joint name = "panto_a5" type="revolute">
    <parent link = "panto_base"/>
    <child link = "panto_right_motor"/>
    <origin xyz = "0.085 0 0" rpy="0 0 0"/>
    <limit effort="1000.0" lower="-1.57" upper="1.57" velocity="0.5"/>
    <axis xyz = "0 0 1"/>
    <dynamics damping="0.2" friction="0.1" />
  </joint>

  <link name = "panto_right_link1">
    <visual>
      <geometry>
        <mesh filename="package://pantograph_description/meshes/mesh_link_left_1.stl" scale="0.001 0.001 0.001"/>
      </geometry>
      <material name = "green"/>
      <origin xyz = "0 0 0" rpy = "0 0 0"/>
    </visual>
  </link>

  <joint name = "panto_right_motor_to_link1" type="fixed">
    <parent link = "panto_right_motor"/>
    <child link = "panto_right_link1"/>
    <origin xyz = "0 0 0"/>
  </joint>

  <link name = "panto_right_link2">
    <visual>
      <geometry>
        <mesh filename="package://pantograph_description/meshes/mesh_link_right_2.stl" scale="0.001 0.001 0.001"/>
      </geometry>
      <material name = "green"/>
      <origin xyz = "0 0 0" rpy = "0 0 0"/>
    </visual>
  </link>

  <joint name = "panto_a4" type="revolute">
    <parent link = "panto_right_link1"/>
    <child link = "panto_right_link2"/>
    <origin xyz = "0.1 0 0" rpy="0 0 0"/>
    <limit effort="1000.0" lower="-1.57" upper="1.57" velocity="0.5"/>
    <axis xyz = "0 0 1"/>
    <dynamics damping="0.2" friction="0.1" />
  </joint>

  <!-- ==========  Test universal joint at end effector =========== -->
  <!-- tool pitch angle-->
  <link name="tool_theta_link"/>

  <joint name="tool_theta_joint" type="continuous">
    <parent link= "panto_tool0"/>
    <child link= "tool_theta_link"/>
    <origin xyz = "0 0 0" rpy="0 0 0"/>
    <axis xyz="0 0 1"/>
  </joint>

  <!-- tool roll angle-->
  <link name = "tool_phi_link">
    <visual>
      <geometry>
        <cylinder length = "0.2" radius = "0.0025"/>
      </geometry>
      <material name = "white_alpha"/>
      <origin xyz = "0 0 0.1" rpy = "0 0 0"/>
    </visual>
  </link>

  <joint name="tool_phi_joint" type="continuous">
    <origin rpy="0 0 0" xyz="0 0 0"/>
    <parent link="tool_theta_link"/>
    <child link="tool_phi_link"/>
    <axis xyz="0 1 0"/>
  </joint>

  <!-- ==========  Test needle insertion DoF =========== -->
  <link name = "needle_interaction_link"/>
  <joint name="needle_interaction_joint" type="prismatic">
    <parent link= "tool_phi_link"/>
    <child link= "needle_interaction_link"/>
    <origin xyz = "0 0 0.1" rpy="0 0 0"/>
    <limit effort="1000.0" lower="0.5" upper="-0.5" velocity="0.5"/>
    <axis xyz="0 0 1"/>
  </joint>

  </xacro:macro>
</robot>
