<?xml version = "1.0"?>
<robot xmlns:xacro="http://www.ros.org/wiki/xacro">

  <xacro:macro name="pantograph" params="parent *origin">

  <material name="blue">
    <color rgba="0.0 0.0 0.8 1.0"/>
  </material>

  <material name="green">
    <color rgba="0.0 0.8 0.0 1.0"/>
  </material>

  <material name="orange">
    <color rgba="${255/255} ${108/255} ${10/255} 1.0"/>
  </material>

  <!-- ========== Base link ========== -->

  <link name = "panto_base">
    <visual>
      <geometry>
        <box size = "0.082 0.050 0.03"/>
      </geometry>
      <material name = "blue"/>
      <origin xyz="0 0 0" rpy="0 0 0" />
    </visual>
  </link>

  <joint name="panto_root_joint" type="fixed">
      <xacro:insert_block name="origin" />
      <parent link="${parent}"/>
      <child link="panto_base"/>
  </joint>

  <!-- ==========  Right arm (as seen from behind) =========== -->

  <link name = "panto_right_motor">
    <visual>
      <geometry>
        <cylinder length = "0.1" radius = "0.05"/>
      </geometry>
      <material name = "green"/>
      <origin xyz = "0 0 0.05"/>
    </visual>
  </link>

  <joint name = "panto_right_joint" type="revolute">
    <parent link = "panto_base"/>
    <child link = "panto_right_motor"/>
    <origin xyz = "0.041 0 0" rpy="0 0 0"/>
    <limit effort="1000.0" lower="-1.57" upper="1.57" velocity="0.5"/>
    <axis xyz = "0 0 1"/>
    <dynamics damping="0.2" friction="0.1" />
  </joint>

  <link name = "panto_right_link1">
    <visual>
      <geometry>
        <box size = "0.1 0.03 0.03"/>
      </geometry>
      <material name = "blue"/>
      <origin xyz = "0 0 0" rpy = "0 0 0"/>
    </visual>
  </link>

  <joint name = "panto_right_motor_to_link1" type="fixed">
    <parent link = "panto_right_motor"/>
    <child link = "panto_right_link1"/>
    <origin xyz = "0 0 0"/>
  </joint>

  <!--
  <link name = "panto_right_link2">
    <visual>
      <geometry>
        <box size = "0.165 0.03 0.03"/>
      </geometry>
      <material name = "blue"/>
      <origin xyz = "0.0825 0 0" rpy = "0 0 0" />
    </visual>
  </link>

  <joint name = "panto_right_joint2" type="revolute">
    <parent link = "panto_right_link1"/>
    <child link = "panto_right_link2"/>
    <origin xyz = "0.3 0 0.13"/>
    <limit effort="1000.0" lower="-1.57" upper="1.57" velocity="0.5"/>
    <axis xyz = "0 0 1"/>
    <dynamics damping="0.2" friction="0.1" />
  </joint>
  -->


  <!-- ==========  Left arm (as seen from behind) =========== -->

  <link name = "panto_left_motor">
    <visual>
      <geometry>
        <cylinder length = "0.1" radius = "0.05"/>
      </geometry>
      <material name = "green"/>
      <origin xyz = "0 0 0.05"/>
    </visual>
  </link>

  <joint name = "panto_left_joint" type="revolute">
    <parent link = "panto_base"/>
    <child link = "panto_left_motor"/>
    <origin xyz = "-0.041 0 0" rpy="0 0 0"/>
    <limit effort="1000.0" lower="-1.57" upper="1.57" velocity="0.5"/>
    <axis xyz = "0 0 1"/>
    <dynamics damping="0.2" friction="0.1" />
  </joint>

  <!-- ==========  Tool link (orange sphere) =========== -->

  </xacro:macro>
</robot>
